<?xml version="1.0"?>
<robot xmlns:xacro="http://www.ros.org/wiki/xacro" name="multishape">

  <link name="base_footprint"/>

  <link name="base_link">
    <visual>
      <geometry>
        <box size="1.0 0.8 0.1"/>
      </geometry>
      <material name="LightGrey">
        <color rgba="0.7 0.7 0.7 1.0"/>
      </material>
    </visual>
    <collision>
      <geometry>
        <box size="1.0 0.8 0.1"/>
      </geometry>
    </collision>
    <inertial>
      <mass value="1.0"/>
      <origin xyz="0.0 0.0 0.0" rpy="0.0 0.0 0.0"/>
      <inertia ixx="0.1" ixy="0.0" ixz="0.0" iyy="0.1" iyz="0.0" izz="0.1"/>
    </inertial>
  </link>

  <joint name="base_joint" type="fixed">
    <origin xyz="0.0 0.0 0.2" rpy="0.0 0.0 0.0"/>
    <parent link="base_footprint"/>
    <child link="base_link"/>
  </joint>

  <xacro:macro name="wheel" params="name x y">
    <link name="wheel_${name}_link">
      <visual>
        <geometry>
          <cylinder radius="0.15" length="0.1"/>
        </geometry>
        <material name="LightGrey">
          <color rgba="0.7 0.7 0.7 1.0"/>
        </material>
      </visual>
      <collision>
        <geometry>
          <cylinder radius="0.15" length="0.1"/>
        </geometry>
      </collision>
      <inertial>
        <mass value="0.55"/>
        <origin xyz="0.0 0.0 0.0" rpy="0.0 0.0 0.0"/>
        <inertia ixx="0.01" ixy="0.0" ixz="0.0" iyy="0.01" iyz="0.0" izz="0.01"/>
      </inertial>
    </link>

    <joint name="wheel_${name}_joint" type="continuous">
      <origin xyz="${x} ${y} 0.0" rpy="1.570796326795 0.0 0.0"/>
      <parent link="base_link"/>
      <child link="wheel_${name}_link"/>
      <axis xyz="0.0 0.0 1.0"/>
    </joint>
  </xacro:macro>

  <xacro:wheel name="front_right" x="0.3" y="0.45"/>
  <xacro:wheel name="rear_right" x="-0.3" y="0.45"/>
  <xacro:wheel name="rear_left" x="-0.3" y="-0.45"/>
  <xacro:wheel name="front_left" x="0.3" y="-0.45"/>

<gazebo>
  <plugin name="skid_steer_drive_controller" filename="libgazebo_ros_skid_steer_drive.so">
    <updateRate>100.0</updateRate>
    <robotNamespace>/</robotNamespace>
    <leftFrontJoint>wheel_front_left_joint</leftFrontJoint>
    <rightFrontJoint>wheel_front_right_joint</rightFrontJoint>
    <leftRearJoint>wheel_rear_left_joint</leftRearJoint>
    <rightRearJoint>wheel_rear_right_joint</rightRearJoint>
    <wheelSeparation>0.4</wheelSeparation>
    <wheelDiameter>0.3</wheelDiameter>
    <robotBaseFrame>base_link</robotBaseFrame>
    <torque>5</torque>
    <topicName>cmd_vel</topicName>
    <broadcastTF>false</broadcastTF>
  </plugin>
</gazebo>

</robot>
