<?xml version="1.0"?>
<robot name="rover">
<link name="base_footprint">
    
</link>
    <link name="base_link">
        <visual>
            <geometry>
                <box size="0.75 0.4 0.1" />
            </geometry>
            <material name="LightGrey">
                <color rgba="0.6 0.6 0.5 1.0"/>
            </material>
        </visual>
    </link>

    <joint name="base_joint" type="fixed">
        <parent link="base_footprint"/>
        <child link="base_link"/>
        <origin xyz="0.0 0.0 0.2" rpy="0.0 0.0 0.0"/>
    </joint>
    
 <link name="wheel_front_left_link">
  <visual>
    <geometry>
      <cylinder radius="0.15" length="0.1"/>
    </geometry>
    <material name="LightGrey">
      <color rgba="0.7 0.7 0.7 1.0"/>
    </material>
  </visual>
  <collision>
    <geometry>
        <mesh filename="package://mobile_robot/meshes/left_tire.stl" scale="0.01 0.01 0.01"/>
    </geometry>
  </collision>
  <inertial>
    <mass value="0.0"/>
    <origin xyz="0.0 0.0 0.0" rpy="0.0 0.0 0.0"/>
    <inertia ixx="0.0" ixy="0.0" ixz="0.0" iyy="0.0" iyz="0.0" izz="0.0"/>
  </inertial>
 </link>

 <joint name="wheel_front_left_joint" type="continuous">
  <origin xyz="0.3 -0.5 0.0" rpy="1.57 0.0 0.0"/>
  <parent link="base_link"/>
  <child link="wheel_front_left_link"/>
  <axis xyz="0.0 0.0 1.0"/>
  <limit lower="0.0" upper="0.0" effort="0.0" velocity="0.0"/>
 </joint>

</robot>
